<!--Promise报错不会阻止 Promise外部执行-->
<!DOCTYPE html>
<html>

	<head>
		<meta charset="UTF-8">
		<title></title>
	</head>

	<body>
		<script type="text/javascript">
			const someAsyncThing = function() {
				return new Promise(function(resolve, reject) {
					// 下面一行会报错，因为x没有声明
					resolve(x + 2);
				});
			};

			someAsyncThing().then(function() {
				console.log('everything is great');
			});

			setTimeout(() => {
				console.log(123) //正常执行
			}, 2000);

			//一般总是建议，Promise 对象后面要跟catch方法，这样可以处理 Promise 内部发生的错误。catch方法返回的还是一个 Promise 对象，因此后面还可以接着调用then方法。
			//正常用法
			someAsyncThing()
			.catch(function(error) {
				console.log('oh no', error);
			})
			.then(function() {
				console.log('carry on');
			});
		</script>
	</body>

</html>